Traceback (most recent call last):
  File "C:\Python34\lib\site-packages\requests\packages\urllib3\util\ssl_.py", line 295, in ssl_wrap_socket
    context.load_verify_locations(ca_certs, ca_cert_dir)
FileNotFoundError: [Errno 2] No such file or directory

During handling of the above exception, another exception occurred:

Traceback (most recent call last):
  File "C:\Python34\lib\site-packages\requests\adapters.py", line 423, in send
    timeout=timeout
  File "C:\Python34\lib\site-packages\requests\packages\urllib3\connectionpool.py", line 595, in urlopen
    chunked=chunked)
  File "C:\Python34\lib\site-packages\requests\packages\urllib3\connectionpool.py", line 352, in _make_request
    self._validate_conn(conn)
  File "C:\Python34\lib\site-packages\requests\packages\urllib3\connectionpool.py", line 831, in _validate_conn
    conn.connect()
  File "C:\Python34\lib\site-packages\requests\packages\urllib3\connection.py", line 289, in connect
    ssl_version=resolved_ssl_version)
  File "C:\Python34\lib\site-packages\requests\packages\urllib3\util\ssl_.py", line 297, in ssl_wrap_socket
    raise SSLError(e)
requests.packages.urllib3.exceptions.SSLError: [Errno 2] No such file or directory

During handling of the above exception, another exception occurred:

Traceback (most recent call last):
  File "hufsgrade.py", line 289, in login
  File "C:\Python34\lib\site-packages\requests\sessions.py", line 522, in post
    return self.request('POST', url, data=data, json=json, **kwargs)
  File "C:\Python34\lib\site-packages\requests\sessions.py", line 475, in request
    resp = self.send(prep, **send_kwargs)
  File "C:\Python34\lib\site-packages\requests\sessions.py", line 596, in send
    r = adapter.send(request, **kwargs)
  File "C:\Python34\lib\site-packages\requests\adapters.py", line 497, in send
    raise SSLError(e, request=request)
requests.exceptions.SSLError: [Errno 2] No such file or directory
Traceback (most recent call last):
  File "C:\Python34\lib\site-packages\requests\packages\urllib3\util\ssl_.py", line 295, in ssl_wrap_socket
    context.load_verify_locations(ca_certs, ca_cert_dir)
FileNotFoundError: [Errno 2] No such file or directory

During handling of the above exception, another exception occurred:

Traceback (most recent call last):
  File "C:\Python34\lib\site-packages\requests\adapters.py", line 423, in send
    timeout=timeout
  File "C:\Python34\lib\site-packages\requests\packages\urllib3\connectionpool.py", line 595, in urlopen
    chunked=chunked)
  File "C:\Python34\lib\site-packages\requests\packages\urllib3\connectionpool.py", line 352, in _make_request
    self._validate_conn(conn)
  File "C:\Python34\lib\site-packages\requests\packages\urllib3\connectionpool.py", line 831, in _validate_conn
    conn.connect()
  File "C:\Python34\lib\site-packages\requests\packages\urllib3\connection.py", line 289, in connect
    ssl_version=resolved_ssl_version)
  File "C:\Python34\lib\site-packages\requests\packages\urllib3\util\ssl_.py", line 297, in ssl_wrap_socket
    raise SSLError(e)
requests.packages.urllib3.exceptions.SSLError: [Errno 2] No such file or directory

During handling of the above exception, another exception occurred:

Traceback (most recent call last):
  File "hufsgrade.py", line 289, in login
  File "C:\Python34\lib\site-packages\requests\sessions.py", line 522, in post
    return self.request('POST', url, data=data, json=json, **kwargs)
  File "C:\Python34\lib\site-packages\requests\sessions.py", line 475, in request
    resp = self.send(prep, **send_kwargs)
  File "C:\Python34\lib\site-packages\requests\sessions.py", line 596, in send
    r = adapter.send(request, **kwargs)
  File "C:\Python34\lib\site-packages\requests\adapters.py", line 497, in send
    raise SSLError(e, request=request)
requests.exceptions.SSLError: [Errno 2] No such file or directory
